Workbook

Sheet Sheet1
A1: كود | B1: بيان | C1: السعر | F1: العدد | G1: البيـــــــــــــــــــــــــــــــــــــــــــــــــــــــــــــــــــــــــــــــــان | H1: السعر | I1: الاجمالي | J1: المجموع | K1: =J105 -> 385.5
A2: 313060010 | B2: مواسير 20 مم (BR BR PN20) - كيسيل | C2: 48.75 | I2: =Table4[[#This Row],[السعر]]*Table4[[#This Row],[العدد]] -> 0 | J2: =Sheet2!#REF!=SUM(Table4[[#This Row],[الاجمالي]]+J1) -> #REF!
A3: 313060011 | B3: مواسير 25 مم (BR BR PN20) - كيسيل | C3: 80 | I3: =Table4[[#This Row],[السعر]]*Table4[[#This Row],[العدد]] -> 0 | J3: =SUM(Table4[[#This Row],[الاجمالي]]) -> 0
A4: 313060012 | B4: مواسير 32 مم (BR BR PN20) - كيسيل | C4: 124.5 | I4: =Table4[[#This Row],[السعر]]*Table4[[#This Row],[العدد]] -> 0 | J4: =SUM(Table4[[#This Row],[الاجمالي]]+J3) -> 0
A5: 313060013 | B5: مواسير 40 مم (BR BR PN20) - كيسيل | C5: 185 | I5: =Table4[[#This Row],[السعر]]*Table4[[#This Row],[العدد]] -> 0 | J5: =SUM(Table4[[#This Row],[الاجمالي]]+J4) -> 0
A6: 313060014 | B6: مواسير 50 مم (BR BR PN20) - كيسيل | C6: 290 | I6: =Table4[[#This Row],[السعر]]*Table4[[#This Row],[العدد]] -> 0 | J6: =SUM(Table4[[#This Row],[الاجمالي]]+J5) -> 0
A7: 313060015 | B7: مواسير 63 مم (BR BR PN20) - كيسيل | C7: 443 | I7: =Table4[[#This Row],[السعر]]*Table4[[#This Row],[العدد]] -> 0 | J7: =SUM(Table4[[#This Row],[الاجمالي]]+J6) -> 0
A8: 313060016 | B8: مواسير 75 مم (BR BR PN20) - كيسيل | C8: 635.5 | I8: =Table4[[#This Row],[السعر]]*Table4[[#This Row],[العدد]] -> 0 | J8: =SUM(Table4[[#This Row],[الاجمالي]]+J7) -> 0
A9: 313060017 | B9: مواسير 90 مم (BR BR PN20) - كيسيل | C9: 915 | I9: =Table4[[#This Row],[السعر]]*Table4[[#This Row],[العدد]] -> 0 | J9: =SUM(Table4[[#This Row],[الاجمالي]]+J8) -> 0
A10: 313060018 | B10: مواسير 110 مم (BR BR PN20) - كيسيل | C10: 1375 | I10: =Table4[[#This Row],[السعر]]*Table4[[#This Row],[العدد]] -> 0 | J10: =SUM(Table4[[#This Row],[الاجمالي]]+J9) -> 0
A11: 313070010 | B11: مواسير 20 مم (PN25) - كيسيل | C11: 56.75 | I11: =Table4[[#This Row],[السعر]]*Table4[[#This Row],[العدد]] -> 0 | J11: =SUM(Table4[[#This Row],[الاجمالي]]+J10) -> 0
A12: 313070011 | B12: مواسير 25 مم (PN25) - كيسيل | C12: 93.25 | I12: =Table4[[#This Row],[السعر]]*Table4[[#This Row],[العدد]] -> 0 | J12: =SUM(Table4[[#This Row],[الاجمالي]]+J11) -> 0
A13: 313070012 | B13: مواسير 32 مم (PN25) - كيسيل | C13: 145.5 | I13: =Table4[[#This Row],[السعر]]*Table4[[#This Row],[العدد]] -> 0 | J13: =SUM(Table4[[#This Row],[الاجمالي]]+J12) -> 0
A14: 313070013 | B14: مواسير 40 مم (PN25) - كيسيل | C14: 215.75 | I14: =Table4[[#This Row],[السعر]]*Table4[[#This Row],[العدد]] -> 0 | J14: =SUM(Table4[[#This Row],[الاجمالي]]+J13) -> 0
A15: 313070014 | B15: مواسير 50 مم (PN25) - كيسيل | C15: 338 | I15: =Table4[[#This Row],[السعر]]*Table4[[#This Row],[العدد]] -> 0 | J15: =SUM(Table4[[#This Row],[الاجمالي]]+J14) -> 0
... A41: 353010015 | B41: كوع 45 درجة كيسيل 50 مم | C41: 43.5 | I41: =Table4[[#This Row],[السعر]]*Table4[[#This Row],[العدد]] -> 0 | J41: =SUM(Table4[[#This Row],[الاجمالي]]+J40) -> 0
A42: 353010016 | B42: كوع 45 درجة كيسيل 75 مم | C42: 64 | F42: 2 | G42: كوع 45 درجة كيسيل 75 مم | H42: 64 | I42: =Table4[[#This Row],[السعر]]*Table4[[#This Row],[العدد]] -> 128 | J42: =SUM(Table4[[#This Row],[الاجمالي]]+J41) -> 128
A43: 353010017 | B43: كوع 45 درجة كيسيل 110 مم | C43: 110.25 | I43: =Table4[[#This Row],[السعر]]*Table4[[#This Row],[العدد]] -> 0 | J43: =SUM(Table4[[#This Row],[الاجمالي]]+J42) -> 128
A44: 353020015 | B44: كوع 90 درجة كيسيل 50 مم | C44: 68.25 | I44: =Table4[[#This Row],[السعر]]*Table4[[#This Row],[العدد]] -> 0 | J44: =SUM(Table4[[#This Row],[الاجمالي]]+J43) -> 128
A45: 353020016 | B45: كوع 90 درجة كيسيل 75 مم | C45: 128.75 | F45: 2 | G45: كوع 90 درجة كيسيل 75 مم | H45: 128.75 | I45: =Table4[[#This Row],[السعر]]*Table4[[#This Row],[العدد]] -> 257.5 | J45: =SUM(Table4[[#This Row],[الاجمالي]]+J44) -> 385.5
A46: 353020017 | B46: كوع 90 درجة كيسيل 110 مم | C46: 323.25 | I46: =Table4[[#This Row],[السعر]]*Table4[[#This Row],[العدد]] -> 0 | J46: =SUM(Table4[[#This Row],[الاجمالي]]+J45) -> 385.5
A47: 313099110 | B47: ماكينة لحام بولي 20-32 مم سمارت هوم | C47: 2850 | I47: =Table4[[#This Row],[السعر]]*Table4[[#This Row],[العدد]] -> 0 | J47: =SUM(Table4[[#This Row],[الاجمالي]]+J46) -> 385.5
A48: 313099111 | B48: ماكينة لحام بولي 20-63 مم سمارت هوم | C48: 4100 | I48: =Table4[[#This Row],[السعر]]*Table4[[#This Row],[العدد]] -> 0 | J48: =SUM(Table4[[#This Row],[الاجمالي]]+J47) -> 385.5
A49: 377090010 | B49: منظف مواسير سمارت هوم 125 مل | C49: 115 | I49: =Table4[[#This Row],[السعر]]*Table4[[#This Row],[العدد]] -> 0 | J49: =SUM(Table4[[#This Row],[الاجمالي]]+J48) -> 385.5
A50: 377090011 | B50: منظف مواسير سمارت هوم 500 مل | C50: 310 | I50: =Table4[[#This Row],[السعر]]*Table4[[#This Row],[العدد]] -> 0 | J50: =SUM(Table4[[#This Row],[الاجمالي]]+J49) -> 385.5
A51: 385010010 | B51: شريط عزل (تيفلون) سمارت هوم | C51: 18.5 | I51: =Table4[[#This Row],[السعر]]*Table4[[#This Row],[العدد]] -> 0 | J51: =SUM(Table4[[#This Row],[الاجمالي]]+J50) -> 385.5
A52: 385010011 | B52: شريط لحام (شكرتون) سمارت هوم | C52: 22 | I52: =Table4[[#This Row],[السعر]]*Table4[[#This Row],[العدد]] -> 0 | J52: =SUM(Table4[[#This Row],[الاجمالي]]+J51) -> 385.5
A53: 313093001 | B53: جلبة 20 مم | C53: 6.5 | I53: =Table4[[#This Row],[السعر]]*Table4[[#This Row],[العدد]] -> 0 | J53: =SUM(Table4[[#This Row],[الاجمالي]]+J52) -> 385.5
A54: 313093002 | B54: جلبة 25 مم | C54: 9.25 | I54: =Table4[[#This Row],[السعر]]*Table4[[#This Row],[العدد]] -> 0 | J54: =SUM(Table4[[#This Row],[الاجمالي]]+J53) -> 385.5
A55: 313093003 | B55: جلبة 32 مم | C55: 14.75 | I55: =Table4[[#This Row],[السعر]]*Table4[[#This Row],[العدد]] -> 0 | J55: =SUM(Table4[[#This Row],[الاجمالي]]+J54) -> 385.5
A56: 313093004 | B56: جلبة 40 مم | C56: 26.25 | I56: =Table4[[#This Row],[السعر]]*Table4[[#This Row],[العدد]] -> 0 | J56: =SUM(Table4[[#This Row],[الاجمالي]]+J55) -> 385.5
A57: 313093005 | B57: جلبة 50 مم | C57: 45 | I57: =Table4[[#This Row],[السعر]]*Table4[[#This Row],[العدد]] -> 0 | J57: =SUM(Table4[[#This Row],[الاجمالي]]+J56) -> 385.5
... A104: 313060008 | B104: مواسير 90 مم (BR BR PN20) BR | C104: 915 | I104: =Table4[[#This Row],[السعر]]*Table4[[#This Row],[العدد]] -> 0 | J104: =SUM(Table4[[#This Row],[الاجمالي]]+J103) -> 385.5
A105: 313060009 | B105: مواسير 110 مم (BR BR PN20) BR | C105: 1375 | J105: =SUM(Table4[[#This Row],[الاجمالي]]+J104) -> 385.5
A106: 313070001 | B106: مواسير 20 مم (PN25) BR | C106: 56.75
A107: 313070002 | B107: مواسير 25 مم (PN25) BR | C107: 93.25
A108: 313070003 | B108: مواسير 32 مم (PN25) BR | C108: 145.5
A109: 313070004 | B109: مواسير 40 مم (PN25) BR | C109: 215.75
A110: 313070005 | B110: مواسير 50 مم (PN25) BR | C110: 338
A111: 313070006 | B111: مواسير 63 مم (PN25) BR | C111: 516
...

Sheet Sheet2
A1: العدد | B1: الكود | C1: الصنف | D1: السعر | E1: احدث سعر | F1: السعر معدل | G1: النوع | H1: تعديل | I1: 3 | J1: Column1
A2: 1 | C2: ماسوره لحام 20مم باننجر | D2: 35.5 | E2: 39.5 | F2: =D2 -> 35.5 | G2: باننجر | H2: =TRIM(SUBSTITUTE(C2, "باننجر", "")) & " " & "باننجر" -> ماسوره لحام 20مم باننجر | I2: ماسوره لحام 20مم باننجر | J2: 1
A3: 2 | C3: ماسوره لحام 25مم باننجر | D3: 59.5 | E3: 66 | F3: =D3 -> 59.5 | G3: باننجر | H3: =TRIM(SUBSTITUTE(C3, "باننجر", "")) & " " & "باننجر" -> ماسوره لحام 25مم باننجر | I3: ماسوره لحام 25مم باننجر | J3: 2
A4: 3 | C4: ماسوره لحام 32مم باننجر | D4: 85.25 | E4: 94.75 | F4: =D4 -> 85.25 | G4: باننجر | H4: =TRIM(SUBSTITUTE(C4, "باننجر", "")) & " " & "باننجر" -> ماسوره لحام 32مم باننجر | I4: ماسوره لحام 32مم باننجر | J4: 3
A5: 4 | C5: ماسوره لحام 50مم باننجر | D5: 204.5 | E5: 227 | F5: =D5 -> 204.5 | G5: باننجر | H5: =TRIM(SUBSTITUTE(C5, "باننجر", "")) & " " & "باننجر" -> ماسوره لحام 50مم باننجر | I5: ماسوره لحام 50مم باننجر | J5: 4
A6: 5 | C6: ماسوره لحام فايبر اسود 25 مم باننجر | D6: 90.25 | E6: 100.25 | F6: =D6 -> 90.25 | G6: باننجر | H6: =TRIM(SUBSTITUTE(C6, "باننجر", "")) & " " & "باننجر" -> ماسوره لحام فايبر اسود 25 مم باننجر | I6: ماسوره لحام فايبر اسود 25 مم باننجر | J6: 5
A7: 6 | C7: ماسوره لحام فايبر اسود 32مم باننجر | D7: 131.75 | E7: 146.25 | F7: =D7 -> 131.75 | G7: باننجر | H7: =TRIM(SUBSTITUTE(C7, "باننجر", "")) & " " & "باننجر" -> ماسوره لحام فايبر اسود 32مم باننجر | I7: ماسوره لحام فايبر اسود 32مم باننجر | J7: 6
A8: 7 | C8: كوع لحام 45 درجه 20 مم باننجر | D8: 24.25 | E8: 27 | F8: =D8 -> 24.25 | G8: باننجر | H8: =TRIM(SUBSTITUTE(C8, "باننجر", "")) & " " & "باننجر" -> كوع لحام 45 درجه 20 مم باننجر | I8: كوع لحام 45 درجه 20 مم باننجر | J8: 7
A9: 8 | C9: كوع لحام 45 درجه 25 مم باننجر | D9: 27.5 | E9: 30.5 | F9: =D9 -> 27.5 | G9: باننجر | H9: =TRIM(SUBSTITUTE(C9, "باننجر", "")) & " " & "باننجر" -> كوع لحام 45 درجه 25 مم باننجر | I9: كوع لحام 45 درجه 25 مم باننجر | J9: 8
A10: 9 | C10: كوع لحام 45 درجه 32 مم باننجر | D10: 41 | E10: 45.5 | F10: =D10 -> 41 | G10: باننجر | H10: =TRIM(SUBSTITUTE(C10, "باننجر", "")) & " " & "باننجر" -> كوع لحام 45 درجه 32 مم باننجر | I10: كوع لحام 45 درجه 32 مم باننجر | J10: 9
A11: 10 | C11: كوع لحام 45 درجه 50 مم باننجر | D11: 144.5 | E11: 160.5 | F11: =D11 -> 144.5 | G11: باننجر | H11: =TRIM(SUBSTITUTE(C11, "باننجر", "")) & " " & "باننجر" -> كوع لحام 45 درجه 50 مم باننجر | I11: كوع لحام 45 درجه 50 مم باننجر | J11: 10
A12: 11 | C12: كوع لحام 20 مم 90درجه باننجر | D12: 14.25 | E12: 15.75 | F12: =D12 -> 14.25 | G12: باننجر | H12: =TRIM(SUBSTITUTE(C12, "باننجر", "")) & " " & "باننجر" -> كوع لحام 20 مم 90درجه باننجر | I12: كوع لحام 20 مم 90درجه باننجر | J12: 11
A13: 12 | C13: كوع لحام 25 مم 90درجه باننجر | D13: 19.75 | E13: 22 | F13: =D13 -> 19.75 | G13: باننجر | H13: =TRIM(SUBSTITUTE(C13, "باننجر", "")) & " " & "باننجر" -> كوع لحام 25 مم 90درجه باننجر | I13: كوع لحام 25 مم 90درجه باننجر | J13: 12
... A78: 77 | C78: محبس بليه 2 لاكور 40 مم باننجر | D78: 1233.5 | E78: 1369.25 | F78: =D78 -> 1233.5 | G78: باننجر | H78: =TRIM(SUBSTITUTE(C78, "باننجر", "")) & " " & "باننجر" -> محبس بليه 2 لاكور 40 مم باننجر | I78: محبس بليه 2 لاكور 40 مم باننجر | J78: 77
A79: 78 | C79: محبس بليه 2 لاكور 50 مم باننجر | D79: 1831 75 | E79: 2033.5 | F79: =D79 -> 1831 75 | G79: باننجر | H79: =TRIM(SUBSTITUTE(C79, "باننجر", "")) & " " & "باننجر" -> محبس بليه 2 لاكور 50 مم باننجر | I79: محبس بليه 2 لاكور 50 مم باننجر | J79: 78
A80: 79 | C80: محبس بليه 2 لاكور 63 مم باننجر | D80: 3058 | E80: 3394.5 | F80: =D80 -> 3058 | G80: باننجر | H80: =TRIM(SUBSTITUTE(C80, "باننجر", "")) & " " & "باننجر" -> محبس بليه 2 لاكور 63 مم باننجر | I80: محبس بليه 2 لاكور 63 مم باننجر | J80: 79
A81: 1 | C81: ماسوره 32 مم كيسيل | D81: 52 | E81: 57.75 | F81: =D81 -> 52 | G81: كيسيل | H81: =TRIM(SUBSTITUTE(Sheet2!$C81, "كيسيل", "")) & " " & "كيسيل" -> ماسوره 32 مم كيسيل | I81: ماسوره 32 مم كيسيل | J81: 1
A82: 2 | C82: ماسوره 50 مم كيسيل | D82: 66.25 | E82: 73.5 | F82: =D82 -> 66.25 | G82: كيسيل | H82: =TRIM(SUBSTITUTE(Sheet2!$C82, "كيسيل", "")) & " " & "كيسيل" -> ماسوره 50 مم كيسيل | I82: ماسوره 50 مم كيسيل | J82: 2
A83: 3 | C83: ماسوره 75 مم كيسيل | D83: 93.5 | E83: 103.75 | F83: =D83 -> 93.5 | G83: كيسيل | H83: =TRIM(SUBSTITUTE(Sheet2!$C83, "كيسيل", "")) & " " & "كيسيل" -> ماسوره 75 مم كيسيل | I83: ماسوره 75 مم كيسيل | J83: 3
A84: 4 | C84: ماسوره 110 مم كيسيل | D84: 181.75 | E84: 201.75 | F84: =D84 -> 181.75 | G84: كيسيل | H84: =TRIM(SUBSTITUTE(Sheet2!$C84, "كيسيل", "")) & " " & "كيسيل" -> ماسوره 110 مم كيسيل | I84: ماسوره 110 مم كيسيل | J84: 4
A85: 5 | C85: ماسوره 160 مم كيسيل | D85: 372.5 | E85: 413.5 | F85: =D85 -> 372.5 | G85: كيسيل | H85: =TRIM(SUBSTITUTE(Sheet2!$C85, "كيسيل", "")) & " " & "كيسيل" -> ماسوره 160 مم كيسيل | I85: ماسوره 160 مم طول 6 متر كيسيل | J85: 5
A86: 6 | C86: ماسوره 63 مم كيسيل | D86: 79.75 | F86: =D86 -> 79.75 | G86: كيسيل | H86: =TRIM(SUBSTITUTE(Sheet2!$C86, "كيسيل", "")) & " " & "كيسيل" -> ماسوره 63 مم كيسيل | I86: ماسوره 63 مم كيسيل | J86: 6
A87: 7 | C87: يارده 63 مم 100 سم كيسيل | D87: 85 | E87: 94.25 | F87: =D87 -> 85 | G87: كيسيل | H87: =TRIM(SUBSTITUTE(Sheet2!$C87, "كيسيل", "")) & " " & "كيسيل" -> يارده 63 مم 100 سم كيسيل | I87: يارده 63 مم 100 سم كيسيل | J87: 7
A88: 8 | C88: يارده 75 مم 100 سم كيسيل | D88: 97 | E88: 107.75 | F88: =D88 -> 97 | G88: كيسيل | H88: =TRIM(SUBSTITUTE(Sheet2!$C88, "كيسيل", "")) & " " & "كيسيل" -> يارده 75 مم 100 سم كيسيل | I88: يارده 75 مم 100 سم كيسيل | J88: 8
A89: 9 | C89: يارده 110 مم 100 سم كيسيل | D89: 197.75 | E89: 219.5 | F89: =D89 -> 197.75 | G89: كيسيل | H89: =TRIM(SUBSTITUTE(Sheet2!$C89, "كيسيل", "")) & " " & "كيسيل" -> يارده 110 مم 100 سم كيسيل | I89: يارده 110 مم 100 سم كيسيل | J89: 9
A90: 10 | C90: يارده 110 مم 50 سم كيسيل | D90: 104 | E90: 115.5 | F90: =D90 -> 104 | G90: كيسيل | H90: =TRIM(SUBSTITUTE(Sheet2!$C90, "كيسيل", "")) & " " & "كيسيل" -> يارده 110 مم 50 سم كيسيل | I90: يارده 110 مم 50 سم كيسيل | J90: 10
A91: 11 | C91: کوع 32 مم 45 كيسيل | D91: 23 | E91: 25.5 | F91: =D91 -> 23 | G91: كيسيل | H91: =TRIM(SUBSTITUTE(Sheet2!$C91, "كيسيل", "")) & " " & "كيسيل" -> کوع 32 مم 45 كيسيل | I91: کوع 32 مم 45 كيسيل | J91: 11
A92: 12 | C92: كوع 50 مم 45 كيسيل | D92: 31 | E92: 34.5 | F92: =D92 -> 31 | G92: كيسيل | H92: =TRIM(SUBSTITUTE(Sheet2!$C92, "كيسيل", "")) & " " & "كيسيل" -> كوع 50 مم 45 كيسيل | I92: كوع 50 مم 45 كيسيل | J92: 12
A93: 13 | C93: كوع 63 مم 45 كيسيل | D93: 43.75 | E93: 48.5 | F93: =D93 -> 43.75 | G93: كيسيل | H93: =TRIM(SUBSTITUTE(Sheet2!$C93, "كيسيل", "")) & " " & "كيسيل" -> كوع 63 مم 45 كيسيل | I93: كوع 63 مم 45 كيسيل | J93: 13
A94: 14 | C94: كوع 75 مم 45 كيسيل | D94: 48 | E94: 53.25 | F94: =D94 -> 48 | G94: كيسيل | H94: =TRIM(SUBSTITUTE(Sheet2!$C94, "كيسيل", "")) & " " & "كيسيل" -> كوع 75 مم 45 كيسيل | I94: كوع 75 مم 45 كيسيل | J94: 14
A95: 15 | C95: كوع 110 مم 45 كيسيل | D95: 75.25 | E95: 83.5 | F95: =D95 -> 75.25 | G95: كيسيل | H95: =TRIM(SUBSTITUTE(Sheet2!$C95, "كيسيل", "")) & " " & "كيسيل" -> كوع 110 مم 45 كيسيل | I95: كوع 110 مم 45 كيسيل | J95: 15
A96: 16 | C96: كوع 160 مم 45 كيسيل | D96: 166 | E96: 184.25 | F96: =D96 -> 166 | G96: كيسيل | H96: =TRIM(SUBSTITUTE(Sheet2!$C96, "كيسيل", "")) & " " & "كيسيل" -> كوع 160 مم 45 كيسيل | I96: كوع 160 مم 45 كيسيل | J96: 16
A97: 17 | C97: كوع 32 مم 87.5 كيسيل | D97: 21.25 | E97: 23.5 | F97: =D97 -> 21.25 | G97: كيسيل | H97: =TRIM(SUBSTITUTE(Sheet2!$C97, "كيسيل", "")) & " " & "كيسيل" -> كوع 32 مم 87.5 كيسيل | I97: كوع 32 مم 87.5 كيسيل | J97: 17
A98: 18 | C98: كوع 50 مم 90درجه كيسيل | D98: 30 | E98: 33.25 | F98: =D98 -> 30 | G98: كيسيل | H98: =TRIM(SUBSTITUTE(Sheet2!$C98, "كيسيل", "")) & " " & "كيسيل" -> كوع 50 مم 90درجه كيسيل | I98: كوع 50 مم 90درجه كيسيل | J98: 18
... A177: 97 | C177: بيبه 3 مدخل 63 مخرج 75 مم كيسيل | D177: 302.75 | E177: 336 | F177: =D177 -> 302.75 | G177: كيسيل | H177: =TRIM(SUBSTITUTE(Sheet2!$C177, "كيسيل", "")) & " " & "كيسيل" -> بيبه 3 مدخل 63 مخرج 75 مم كيسيل | I177: بيبه 3 مدخل 63 مخرج 75 مم كيسيل | J177: 97
A178: 1 | C178: ماسوره 4/3 بوصه 2.9 مم 6 متر سمارت هوم | D178: 51 | E178: 56.5 | F178: =D178 -> 51 | G178: سمارت هوم | H178: =TRIM(SUBSTITUTE(Sheet2!$C178, "سمارت هوم", "")) & " " & "سمارت هوم" -> ماسوره 4/3 بوصه 2.9 مم 6 متر سمارت هوم | I178: ماسوره 4/3 بوصه 2.9 مم 6 متر سمارت هوم | J178: 1
A179: 2 | C179: ماسوره 1 بوصه / 1.8 سمارت هوم | D179: 35.25 | E179: 39.25 | F179: =D179 -> 35.25 | G179: سمارت هوم | H179: =TRIM(SUBSTITUTE(Sheet2!$C179, "سمارت هوم", "")) & " " & "سمارت هوم" -> ماسوره 1 بوصه / 1.8 سمارت هوم | I179: ماسوره 1 بوصه / 1.8 سمارت هوم | J179: 2
A180: 5 | C180: ماسوره 32 مم 1.8 سمارت هوم | D180: 32 25 | E180: 35.75 | F180: =D180 -> 32 25 | G180: سمارت هوم | H180: =TRIM(SUBSTITUTE(Sheet2!$C180, "سمارت هوم", "")) & " " & "سمارت هوم" -> ماسوره 32 مم 1.8 سمارت هوم | I180: ماسوره 32 مم 1.8 سمارت هوم | J180: 5
A181: 8 | C181: ماسوره 48 مم 3.7 سمارت هوم | D181: 87 | E181: 96.5 | F181: =D181 -> 87 | G181: سمارت هوم | H181: =TRIM(SUBSTITUTE(Sheet2!$C181, "سمارت هوم", "")) & " " & "سمارت هوم" -> ماسوره 48 مم 3.7 سمارت هوم | I181: ماسوره 48 مم 3.7 سمارت هوم | J181: 8
A182: 10 | C182: ماسوره 60 /3.9 سمارت هوم | D182: 118.5 | E182: 131.5 | F182: =D182 -> 118.5 | G182: سمارت هوم | H182: =TRIM(SUBSTITUTE(Sheet2!$C182, "سمارت هوم", "")) & " " & "سمارت هوم" -> ماسوره 60 /3.9 سمارت هوم | I182: ماسوره 60 /3.9 سمارت هوم | J182: 10
...

Sheet Sheet3
A1: البيان | B1: أحدث سعر
A2: كوع نزل نحاس بلازا
A3: حنفيه بليه ايطالي ١/٢
A4: حنفيه بليه ايطالى ٣/٤
A5: حنفيه بليه ايطالي كبيره لوكس ١
A6: مشترك نيكل مدور ۱/۲ شيلد
A7: بوش ۱/۲*۳/٤ استانلس
A8: بوش 3/4*١ انفت مجلفن
A9: بوش نيكل ١/٢*٣/٨
A10: نبل نيكل شجره لوكس ١/٢
A11: مانيجا سوسته ايطالي
A12: سيفون مفرد حله مصري بلاستيك 3"
A13: سيفون حله بلاستيك ايطالى 3"
... A197: مجري شاور ٤٠ سم استانلس ٣٠٤ ليزر تبليط دوت بلس

Sheet تحديث الجدول
A1: الكود | B1: الباركود | C1: اسم الصنف | D1: الشركة | E1: الوحدة | F1: سعر البيع | G1: الحد الأدني | H1: ملاحظات | I1: النوع | J1: سعر الجملة | K1: الحد الأقصى | L1: الكمية | M1: سعر الشراء | N1: اسم المخزن | O1: المقاس | P1: اللون | Q1: نصف الجملة | R1: سعر جمله 1 | S1: سعر جمله 2 | T1: أقصى نسبة خصم | U1: أقصى كمية بيع | V1: الكود المخزني | W1: نسبة الضريبة | X1: حالة التكرار
C2: ماسوره لحام 20مم باننجر | D2: ادوات صحيه | E2: قطعة | F2: 39.5 | G2: 0 | I2: باننجر | K2: 0 | M2: =F2-F2*17% -> 32.785 | N2: فرع الخمائل مول ت13 | O2: عام | P2: عام | Q2: 0 | R2: 270 | S2: 0 | T2: 0 | U2: 0 | V2: 0 | W2: 0 | X2: غير مكرر
C3: ماسوره لحام 25مم باننجر | D3: ادوات صحيه | F3: 66 | I3: باننجر | M3: =F3-F3*17% -> 54.78 | N3: فرع الخمائل مول ت13 | O3: عام | P3: عام | Q3: 0 | X3: غير مكرر
C4: ماسوره لحام 32مم باننجر | D4: ادوات صحيه | F4: 94.75 | I4: باننجر | M4: =F4-F4*17% -> 78.6425 | N4: فرع الخمائل مول ت13 | O4: عام | P4: عام | Q4: 0 | X4: غير مكرر
C5: ماسوره لحام 50مم باننجر | D5: ادوات صحيه | F5: 227 | I5: باننجر | M5: =F5-F5*17% -> 188.41 | N5: فرع الخمائل مول ت13 | O5: عام | P5: عام | Q5: 0 | X5: غير مكرر
C6: ماسوره لحام فايبر اسود 25 مم باننجر | D6: ادوات صحيه | F6: 100.25 | I6: باننجر | M6: =F6-F6*17% -> 83.2075 | N6: فرع الخمائل مول ت13 | O6: عام | P6: عام | Q6: 0 | X6: غير مكرر
C7: ماسوره لحام فايبر اسود 32مم باننجر | D7: ادوات صحيه | F7: 146.25 | I7: باننجر | M7: =F7-F7*17% -> 121.3875 | N7: فرع الخمائل مول ت13 | O7: عام | P7: عام | Q7: 0 | X7: غير مكرر
C8: كوع لحام 45 درجه 20 مم باننجر | D8: ادوات صحيه | F8: 27 | I8: باننجر | M8: =F8-F8*17% -> 22.41 | N8: فرع الخمائل مول ت13 | O8: عام | P8: عام | Q8: 0 | X8: غير مكرر
C9: كوع لحام 45 درجه 25 مم باننجر | D9: ادوات صحيه | F9: 30.5 | I9: باننجر | M9: =F9-F9*17% -> 25.315 | N9: فرع الخمائل مول ت13 | O9: عام | P9: عام | Q9: 0 | X9: غير مكرر
C10: كوع لحام 45 درجه 32 مم باننجر | D10: ادوات صحيه | F10: 45.5 | I10: باننجر | M10: =F10-F10*17% -> 37.765 | N10: فرع الخمائل مول ت13 | O10: عام | P10: عام | Q10: 0 | X10: غير مكرر
C11: كوع لحام 45 درجه 50 مم باننجر | D11: ادوات صحيه | F11: 160.5 | I11: باننجر | M11: =F11-F11*17% -> 133.215 | N11: فرع الخمائل مول ت13 | O11: عام | P11: عام | Q11: 0 | X11: غير مكرر
C12: كوع لحام 20 مم 90درجه باننجر | D12: ادوات صحيه | F12: 15.75 | I12: باننجر | M12: =F12-F12*17% -> 13.0725 | N12: فرع الخمائل مول ت13 | O12: عام | P12: عام | Q12: 0 | X12: غير مكرر
C13: كوع لحام 25 مم 90درجه باننجر | D13: ادوات صحيه | F13: 22 | I13: باننجر | M13: =F13-F13*17% -> 18.26 | N13: فرع الخمائل مول ت13 | O13: عام | P13: عام | Q13: 0 | X13: غير مكرر
C14: كوع لحام 32 مم 90درجه باننجر | D14: ادوات صحيه | F14: 42 | I14: باننجر | M14: =F14-F14*17% -> 34.86 | N14: فرع الخمائل مول ت13 | O14: عام | P14: عام | Q14: 0 | X14: غير مكرر
... C85: ماسوره 160 مم كيسيل | D85: ادوات صحيه | F85: 413.5 | I85: كيسيل | M85: =F85-F85*17% -> 343.205 | N85: فرع الخمائل مول ت13 | O85: عام | P85: عام | Q85: 0 | X85: غير مكرر
C86: ماسوره 63 مم كيسيل | D86: ادوات صحيه | I86: كيسيل | M86: =F86-F86*17% -> 0 | N86: فرع الخمائل مول ت13 | O86: عام | P86: عام | Q86: 0 | X86: غير مكرر
C87: يارده 63 مم 100 سم كيسيل | D87: ادوات صحيه | F87: 94.25 | I87: كيسيل | M87: =F87-F87*17% -> 78.2275 | N87: فرع الخمائل مول ت13 | O87: عام | P87: عام | Q87: 0 | X87: غير مكرر
C88: يارده 75 مم 100 سم كيسيل | D88: ادوات صحيه | F88: 107.75 | I88: كيسيل | M88: =F88-F88*17% -> 89.4325 | N88: فرع الخمائل مول ت13 | O88: عام | P88: عام | Q88: 0 | X88: غير مكرر
C89: يارده 110 مم 100 سم كيسيل | D89: ادوات صحيه | F89: 219.5 | I89: كيسيل | M89: =F89-F89*17% -> 182.185 | N89: فرع الخمائل مول ت13 | O89: عام | P89: عام | Q89: 0 | X89: غير مكرر
C90: يارده 110 مم 50 سم كيسيل | D90: ادوات صحيه | F90: 115.5 | I90: كيسيل | M90: =F90-F90*17% -> 95.865 | N90: فرع الخمائل مول ت13 | O90: عام | P90: عام | Q90: 0 | X90: غير مكرر
C91: کوع 32 مم 45 كيسيل | D91: ادوات صحيه | F91: 25.5 | I91: كيسيل | M91: =F91-F91*17% -> 21.165 | N91: فرع الخمائل مول ت13 | O91: عام | P91: عام | Q91: 0 | X91: غير مكرر
C92: كوع 50 مم 45 كيسيل | D92: ادوات صحيه | F92: 34.5 | I92: كيسيل | M92: =F92-F92*17% -> 28.635 | N92: فرع الخمائل مول ت13 | O92: عام | P92: عام | Q92: 0 | X92: غير مكرر
C93: كوع 63 مم 45 كيسيل | D93: ادوات صحيه | F93: 48.5 | I93: كيسيل | M93: =F93-F93*17% -> 40.255 | N93: فرع الخمائل مول ت13 | O93: عام | P93: عام | Q93: 0 | X93: غير مكرر
C94: كوع 75 مم 45 كيسيل | D94: ادوات صحيه | F94: 53.25 | I94: كيسيل | M94: =F94-F94*17% -> 44.1975 | N94: فرع الخمائل مول ت13 | O94: عام | P94: عام | Q94: 0 | X94: غير مكرر
C95: كوع 110 مم 45 كيسيل | D95: ادوات صحيه | F95: 83.5 | I95: كيسيل | M95: =F95-F95*17% -> 69.305 | N95: فرع الخمائل مول ت13 | O95: عام | P95: عام | Q95: 0 | X95: غير مكرر
C96: كوع 160 مم 45 كيسيل | D96: ادوات صحيه | F96: 184.25 | I96: كيسيل | M96: =F96-F96*17% -> 152.9275 | N96: فرع الخمائل مول ت13 | O96: عام | P96: عام | Q96: 0 | X96: غير مكرر
C97: كوع 32 مم 87.5 كيسيل | D97: ادوات صحيه | F97: 23.5 | I97: كيسيل | M97: =F97-F97*17% -> 19.505 | N97: فرع الخمائل مول ت13 | O97: عام | P97: عام | Q97: 0 | X97: غير مكرر
C98: كوع 50 مم 90درجه كيسيل | D98: ادوات صحيه | F98: 33.25 | I98: كيسيل | M98: =F98-F98*17% -> 27.5975 | N98: فرع الخمائل مول ت13 | O98: عام | P98: عام | Q98: 0 | X98: غير مكرر
... C236: وصله مرنه 100 سم سمارت هوم | D236: ادوات صحيه | F236: 99.25 | I236: سمارت هوم | M236: =F236-F236*17% -> 82.3775 | N236: فرع الخمائل مول ت13 | O236: عام | P236: عام | Q236: 0 | X236: غير مكرر
C237: وصله شجره مرنه 40 سم سمارت هوم | D237: ادوات صحيه | I237: سمارت هوم | M237: =F237-F237*17% -> 0 | N237: فرع الخمائل مول ت13 | O237: عام | P237: عام | Q237: 0 | X237: غير مكرر
C238: وصله شجره مرنه 50 سم سمارت هوم | D238: ادوات صحيه | I238: سمارت هوم | M238: =F238-F238*17% -> 0 | N238: فرع الخمائل مول ت13 | O238: عام | P238: عام | Q238: 0 | X238: غير مكرر
C239: وصله شجره مرنه 60 سم سمارت هوم | D239: ادوات صحيه | I239: سمارت هوم | M239: =F239-F239*17% -> 0 | N239: فرع الخمائل مول ت13 | O239: عام | P239: عام | Q239: 0 | X239: غير مكرر
C240: وصله مرنه 40 سم بسن خلاط سمارت هوم | D240: ادوات صحيه | F240: 132 | I240: سمارت هوم | M240: =F240-F240*17% -> 109.56 | N240: فرع الخمائل مول ت13 | O240: عام | P240: عام | Q240: 0 | X240: غير مكرر
C241: وصله مرنه 50 سم بسن خلاط سمارت هوم | D241: ادوات صحيه | F241: 143.5 | I241: سمارت هوم | M241: =F241-F241*17% -> 119.105 | N241: فرع الخمائل مول ت13 | O241: عام | P241: عام | Q241: 0 | X241: غير مكرر
C242: وصله مرنه 60 سم بسن خلاط سمارت هوم | D242: ادوات صحيه | F242: 150.75 | I242: سمارت هوم | M242: =F242-F242*17% -> 125.1225 | N242: فرع الخمائل مول ت13 | O242: عام | P242: عام | Q242: 0 | X242: غير مكرر
C243: جلبه 4/3 سمارت هوم | D243: ادوات صحيه | F243: 12 | I243: سمارت هوم | M243: =F243-F243*17% -> 9.96 | N243: فرع الخمائل مول ت13 | O243: عام | P243: عام | Q243: 0 | X243: غير مكرر
C244: جلبه صرف 1 بوصه سمارت هوم | D244: ادوات صحيه | F244: 17.25 | I244: سمارت هوم | M244: =F244-F244*17% -> 14.3175 | N244: فرع الخمائل مول ت13 | O244: عام | P244: عام | Q244: 0 | X244: غير مكرر
C245: جلبه صرف 32 مم سمارت هوم | D245: ادوات صحيه | F245: 16 | I245: سمارت هوم | M245: =F245-F245*17% -> 13.28 | N245: فرع الخمائل مول ت13 | O245: عام | P245: عام | Q245: 0 | X245: غير مكرر
C246: جلبه صرف 48 مم سمارت هوم | D246: ادوات صحيه | F246: 28.5 | I246: سمارت هوم | M246: =F246-F246*17% -> 23.655 | N246: فرع الخمائل مول ت13 | O246: عام | P246: عام | Q246: 0 | X246: غير مكرر
C247: جلبه صرف 60 مم سمارت هوم | D247: ادوات صحيه | F247: 36 | I247: سمارت هوم | M247: =F247-F247*17% -> 29.88 | N247: فرع الخمائل مول ت13 | O247: عام | P247: عام | Q247: 0 | X247: غير مكرر
...
